Workbook

Sheet Resumen
A1: Paso | B1: Entrega | C1: Fecha | D1: Tareas | E1: Hechas | F1: Listas p/desplegar | G1: Pendientes | H1: % hecho | I1: % código listo
A2: 1 | B2: Examen + P1: diseño, costos, ingesta/storage | C2: 24-oct-2026 | D2: =COUNTIF(Matriz!$B$2:$B$52,A2) -> 21 | E2: =COUNTIFS(Matriz!$B$2:$B$52,$A2,Matriz!$N$2:$N$52,"Hecho") -> 15 | F2: =COUNTIFS(Matriz!$B$2:$B$52,$A2,Matriz!$N$2:$N$52,"Listo para desplegar") -> 3 | G2: =COUNTIFS(Matriz!$B$2:$B$52,$A2,Matriz!$N$2:$N$52,"Pendiente") -> 3 | H2: =IF(D2>0,E2/D2,0) -> 0.71428571 | I2: =IF(D2>0,(E2+F2)/D2,0) -> 0.85714286
A3: 2 | B3: P2: pipelines batch + streaming, modelado | C3: 07-nov-2026 | D3: =COUNTIF(Matriz!$B$2:$B$52,A3) -> 14 | E3: =COUNTIFS(Matriz!$B$2:$B$52,$A3,Matriz!$N$2:$N$52,"Hecho") -> 2 | F3: =COUNTIFS(Matriz!$B$2:$B$52,$A3,Matriz!$N$2:$N$52,"Listo para desplegar") -> 8 | G3: =COUNTIFS(Matriz!$B$2:$B$52,$A3,Matriz!$N$2:$N$52,"Pendiente") -> 4 | H3: =IF(D3>0,E3/D3,0) -> 0.14285714 | I3: =IF(D3>0,(E3+F3)/D3,0) -> 0.71428571
A4: 3 | B4: P3: API, asistente, tableros, demo, sustentación | C4: 20-nov-2026 | D4: =COUNTIF(Matriz!$B$2:$B$52,A4) -> 16 | E4: =COUNTIFS(Matriz!$B$2:$B$52,$A4,Matriz!$N$2:$N$52,"Hecho") -> 1 | F4: =COUNTIFS(Matriz!$B$2:$B$52,$A4,Matriz!$N$2:$N$52,"Listo para desplegar") -> 7 | G4: =COUNTIFS(Matriz!$B$2:$B$52,$A4,Matriz!$N$2:$N$52,"Pendiente") -> 8 | H4: =IF(D4>0,E4/D4,0) -> 0.0625 | I4: =IF(D4>0,(E4+F4)/D4,0) -> 0.5
B5: TOTAL | D5: =SUM(D2:D4) -> 51 | E5: =SUM(E2:E4) -> 18 | F5: =SUM(F2:F4) -> 18 | G5: =SUM(G2:G4) -> 15 | H5: =IF(D5>0,E5/D5,0) -> 0.35294118 | I5: =IF(D5>0,(E5+F5)/D5,0) -> 0.70588235
A8: Leyenda
A9: Paso 1 = Entrega 1 (24-oct) · Paso 2 = Entrega 2 (07-nov) · Paso 3 = repositorio 20-nov y sustentación 21-nov.
A10: Hecho = terminado con evidencia. Listo para desplegar = código probado localmente; falta ejecutarlo en GCP.
A11: Estado se elige en la hoja Matriz (lista desplegable); '¿Hecho?', perfiles y resumen se recalculan solos.
A12: Despliegue: orden de comandos. Parámetros, nombres, tablas, columnas, usuarios y permisos: config/control_plataforma.json (editable con `python ops.py panel`).

Sheet Matriz
A1: ID | B1: Paso | C1: Orden | D1: Fecha límite | E1: Fase | F1: Nombre de la tarea | G1: Acción / tarea | H1: Entregable (ruta) | I1: Comando | J1: Depende de | K1: Responsable | L1: Perfil | M1: Apoyo | N1: Estado | O1: ¿Hecho? | P1: Evidencia / observación
A2: P1-01 | B2: 1 | C2: 1 | D2: 24-oct-2026 | E2: Datos | F2: Auditoría de datos H&M | G2: Perfilar filas, nulos, fechas, cardinalidad y cobertura | H2: Word §4 | K2: Nicole Arenas | L2: =IFERROR(INDEX(Perfiles!$B$2:$B$5,MATCH(K2,Perfiles!$A$2:$A$5,0)),"") -> Datos + API + Modelado | M2: Estuardo Oliver | N2: Hecho | O2: =IF(N2="Hecho","Sí","No") -> Sí | P2: 31.8M líneas, 9.08M pedidos, 1.37M clientes, 105,542 artículos
A3: P1-02 | B3: 1 | C3: 2 | D3: 24-oct-2026 | E3: Gestión | F3: Ordenar carpeta y repositorio | G3: Estructura por capas; Amazon/zip archivados; secretos fuera | H3: README.md | K3: Estuardo Oliver | L3: =IFERROR(INDEX(Perfiles!$B$2:$B$5,MATCH(K3,Perfiles!$A$2:$A$5,0)),"") -> ML / Analytics | M3: Winston Quispe | N3: Hecho | O3: =IF(N3="Hecho","Sí","No") -> Sí | P3: data/_archive y .secrets/ fuera de Git
A4: P1-03 | B4: 1 | C4: 3 | D4: 24-oct-2026 | E4: Seguridad | F4: Proteger datos y secretos | G4: .gitignore + regla CI que bloquea CSV/ZIP/tfstate/credenciales | H4: .gitignore, .github/workflows/ci.yml | K4: Winston Quispe | L4: =IFERROR(INDEX(Perfiles!$B$2:$B$5,MATCH(K4,Perfiles!$A$2:$A$5,0)),"") -> Cloud Computing | N4: Hecho | O4: =IF(N4="Hecho","Sí","No") -> Sí | P4: Regla 'Sin datos ni secretos versionados'
A5: P1-04 | B5: 1 | C5: 4 | D5: 24-oct-2026 | E5: Diseño | F5: Justificar stack GCP | G5: Decisión por capa con alternativa descartada | H5: Word §5 | K5: Winston Quispe | L5: =IFERROR(INDEX(Perfiles!$B$2:$B$5,MATCH(K5,Perfiles!$A$2:$A$5,0)),"") -> Cloud Computing | M5: Estuardo Oliver | N5: Hecho | O5: =IF(N5="Hecho","Sí","No") -> Sí | P5: Tabla de ADR
A6: P1-05 | B6: 1 | C6: 5 | D6: 24-oct-2026 | E6: Diseño | F6: Diagrama end-to-end | G6: Fuentes, ingesta, almacenamiento, cómputo, exposición | H6: docs/architecture/arquitectura.png | I6: dot -Tpng docs/architecture/arquitectura_vertical.dot -o docs/architecture/arquitectura.png | K6: Gianmarco Mejia | L6: =IFERROR(INDEX(Perfiles!$B$2:$B$5,MATCH(K6,Perfiles!$A$2:$A$5,0)),"") -> Dashboard / BI | M6: Winston Quispe | N6: Hecho | O6: =IF(N6="Hecho","Sí","No") -> Sí | P6: Graphviz regenerable
A7: P1-06 | B7: 1 | C7: 6 | D7: 24-oct-2026 | E7: Diseño | F7: Integración multifuente | G7: Batch H&M + replay 2026; doble reloj source_t_dat/event_time | H7: Word §6 | J7: P1-01 | K7: Nicole Arenas | L7: =IFERROR(INDEX(Perfiles!$B$2:$B$5,MATCH(K7,Perfiles!$A$2:$A$5,0)),"") -> Datos + API + Modelado | M7: Winston Quispe | N7: Hecho | O7: =IF(N7="Hecho","Sí","No") -> Sí
A8: P1-07 | B8: 1 | C8: 7 | D8: 24-oct-2026 | E8: Diseño | F8: Ingesta y almacenamiento | G8: GCS medallion + BigQuery + Cloud SQL; formatos y particiones | H8: Word §7 | J8: P1-06 | K8: Nicole Arenas | L8: =IFERROR(INDEX(Perfiles!$B$2:$B$5,MATCH(K8,Perfiles!$A$2:$A$5,0)),"") -> Datos + API + Modelado | M8: Winston Quispe | N8: Hecho | O8: =IF(N8="Hecho","Sí","No") -> Sí
A9: P1-08 | B9: 1 | C9: 8 | D9: 24-oct-2026 | E9: Diseño | F9: Escalabilidad Black Friday | G9: Autoescalado, desacople, degradación controlada | H9: Word §8 | K9: Winston Quispe | L9: =IFERROR(INDEX(Perfiles!$B$2:$B$5,MATCH(K9,Perfiles!$A$2:$A$5,0)),"") -> Cloud Computing | M9: Nicole Arenas | N9: Hecho | O9: =IF(N9="Hecho","Sí","No") -> Sí | P9: Escenario 5x en calculadora
A10: P1-09 | B10: 1 | C10: 9 | D10: 24-oct-2026 | E10: Costos | F10: Calculadora y costo por pedido | G10: YAML -> Excel con fórmulas; 4 escenarios; año 1 | H10: docs/entrega1/Calculadora_Costos_GCP.xlsx | I10: python cost/estimate_costs.py | K10: Gianmarco Mejia | L10: =IFERROR(INDEX(Perfiles!$B$2:$B$5,MATCH(K10,Perfiles!$A$2:$A$5,0)),"") -> Dashboard / BI | M10: Winston Quispe | N10: Hecho | O10: =IF(N10="Hecho","Sí","No") -> Sí | P10: Año 1 USD 5,482; USD 0.00098/pedido (Gemini 3.1 Flash-Lite)
A11: P1-10 | B11: 1 | C11: 10 | D11: 24-oct-2026 | E11: Costos | F11: Automatizar control de costos | G11: Precios vía API, budget con alertas, costo real por pedido | H11: cost/, infra/terraform/main.tf | I11: python cost/estimate_costs.py --refresh-prices | J11: P2-01 | K11: Winston Quispe | L11: =IFERROR(INDEX(Perfiles!$B$2:$B$5,MATCH(K11,Perfiles!$A$2:$A$5,0)),"") -> Cloud Computing | M11: Gianmarco Mejia | N11: Listo para desplegar | O11: =IF(N11="Hecho","Sí","No") -> No | P11: Probado local; activar billing export en consola
A12: P1-11 | B12: 1 | C12: 11 | D12: 24-oct-2026 | E12: Resiliencia | F12: DRP / HA | G12: RPO/RTO por componente y runbook | H12: Word §10, docs/runbooks/drp.md | K12: Winston Quispe | L12: =IFERROR(INDEX(Perfiles!$B$2:$B$5,MATCH(K12,Perfiles!$A$2:$A$5,0)),"") -> Cloud Computing | M12: Nicole Arenas | N12: Hecho | O12: =IF(N12="Hecho","Sí","No") -> Sí
A13: P1-12 | B13: 1 | C13: 12 | D13: 24-oct-2026 | E13: BI | F13: Catálogo de KPIs | G13: Metas de datos, streaming, modelo, API, negocio, costo | H13: Word §11 | K13: Gianmarco Mejia | L13: =IFERROR(INDEX(Perfiles!$B$2:$B$5,MATCH(K13,Perfiles!$A$2:$A$5,0)),"") -> Dashboard / BI | M13: Estuardo Oliver | N13: Hecho | O13: =IF(N13="Hecho","Sí","No") -> Sí
A14: P1-13 | B14: 1 | C14: 13 | D14: 24-oct-2026 | E14: Datos | F14: Ingesta Bronze con manifiesto | G14: SHA-256 y filas por archivo; rsync idempotente | H14: ingestion/batch/upload_raw.py | I14: python ingestion/batch/upload_raw.py --manifest-only | K14: Nicole Arenas | L14: =IFERROR(INDEX(Perfiles!$B$2:$B$5,MATCH(K14,Perfiles!$A$2:$A$5,0)),"") -> Datos + API + Modelado | M14: Winston Quispe | N14: Hecho | O14: =IF(N14="Hecho","Sí","No") -> Sí | P14: Manifiesto real en data/manifests/
A15: P1-14 | B15: 1 | C15: 14 | D15: 24-oct-2026 | E15: Infra | F15: Terraform base | G15: Buckets, BigQuery, Pub/Sub+DLQ, IAM, Artifact Registry, budget (valores desde el JSON de control) | H15: infra/terraform/ | I15: python ops.py plan | J15: P1-20 | K15: Winston Quispe | L15: =IFERROR(INDEX(Perfiles!$B$2:$B$5,MATCH(K15,Perfiles!$A$2:$A$5,0)),"") -> Cloud Computing | N15: Listo para desplegar | O15: =IF(N15="Hecho","Sí","No") -> No | P15: validate OK; tipos de variables probados con el JSON generado
A16: P1-15 | B16: 1 | C16: 15 | D16: 24-oct-2026 | E16: Gestión | F16: Documento Word Entrega 1 | G16: Examen + P1 profesional | H16: docs/entrega1/*.docx (+PDF) | J16: P1-01..P1-14 | K16: Estuardo Oliver | L16: =IFERROR(INDEX(Perfiles!$B$2:$B$5,MATCH(K16,Perfiles!$A$2:$A$5,0)),"") -> ML / Analytics | M16: Todo el equipo | N16: Hecho | O16: =IF(N16="Hecho","Sí","No") -> Sí
A17: P1-16 | B17: 1 | C17: 16 | D17: 24-oct-2026 | E17: Gestión | F17: Matriz de auditoría y roles | G17: Tareas, pasos, despliegue y variables | H17: docs/gestion/Matriz_Auditoria_Proyecto.xlsx | I17: python docs/_generadores/build_matriz.py | K17: Estuardo Oliver | L17: =IFERROR(INDEX(Perfiles!$B$2:$B$5,MATCH(K17,Perfiles!$A$2:$A$5,0)),"") -> ML / Analytics | M17: Todo el equipo | N17: Hecho | O17: =IF(N17="Hecho","Sí","No") -> Sí | P17: Este archivo
A18: P1-17 | B18: 1 | C18: 17 | D18: 24-oct-2026 | E18: Infra | F18: Crear proyecto GCP | G18: Proyecto, facturación/créditos, accesos IAM del equipo | H18: Proyecto GCP | I18: ver hoja Despliegue D01-D04 | K18: Winston Quispe | L18: =IFERROR(INDEX(Perfiles!$B$2:$B$5,MATCH(K18,Perfiles!$A$2:$A$5,0)),"") -> Cloud Computing | N18: Pendiente | O18: =IF(N18="Hecho","Sí","No") -> No
A19: P1-18 | B19: 1 | C19: 18 | D19: 24-oct-2026 | E19: Gestión | F19: Publicar repositorio GitHub | G19: Crear repo privado, push y CI en verde | H19: URL del repo | I19: git push -u origin main | J19: P1-17 | K19: Winston Quispe | L19: =IFERROR(INDEX(Perfiles!$B$2:$B$5,MATCH(K19,Perfiles!$A$2:$A$5,0)),"") -> Cloud Computing | M19: Todo el equipo | N19: Pendiente | O19: =IF(N19="Hecho","Sí","No") -> No | P19: Git inicializado localmente
A20: P1-20 | B20: 1 | C20: 19 | D20: 24-oct-2026 | E20: Infra | F20: JSON de control de la plataforma | G20: Parámetros, APIs, cuentas, permisos, usuarios, datasets, tablas, columnas y secretos en un solo JSON validado, editable con el panel web | H20: config/control_plataforma.json | I20: python ops.py config | K20: Winston Quispe | L20: =IFERROR(INDEX(Perfiles!$B$2:$B$5,MATCH(K20,Perfiles!$A$2:$A$5,0)),"") -> Cloud Computing | M20: Todo el equipo | N20: Hecho | O20: =IF(N20="Hecho","Sí","No") -> Sí | P20: 30 tablas, 240 columnas, 28 permisos, 6 usuarios app; CI verifica generados
A21: P1-21 | B21: 1 | C21: 20 | D21: 24-oct-2026 | E21: Infra | F21: Orquestador de despliegue | G21: Un comando por paso, multiplataforma, con log matricial de tiempos | H21: ops.py | I21: python ops.py todo | J21: P1-20 | K21: Winston Quispe | L21: =IFERROR(INDEX(Perfiles!$B$2:$B$5,MATCH(K21,Perfiles!$A$2:$A$5,0)),"") -> Cloud Computing | M21: Nicole Arenas | N21: Listo para desplegar | O21: =IF(N21="Hecho","Sí","No") -> No | P21: config/estado/local probados; comandos de nube pendientes de GCP
A22: P1-19 | B22: 1 | C22: 21 | D22: 24-oct-2026 | E22: Gestión | F22: Revisión y envío Entrega 1 | G22: Revisión cruzada del Word y envío antes de 23:59 | H22: Word enviado | J22: P1-15 | K22: Estuardo Oliver | L22: =IFERROR(INDEX(Perfiles!$B$2:$B$5,MATCH(K22,Perfiles!$A$2:$A$5,0)),"") -> ML / Analytics | M22: Todo el equipo | N22: Pendiente | O22: =IF(N22="Hecho","Sí","No") -> No
A23: P2-01 | B23: 2 | C23: 1 | D23: 07-nov-2026 | E23: Infra | F23: Desplegar infraestructura dev | G23: Bootstrap de estado, plan y apply | H23: Recursos en GCP | I23: python ops.py bootstrap; python ops.py apply | J23: P1-17 | K23: Winston Quispe | L23: =IFERROR(INDEX(Perfiles!$B$2:$B$5,MATCH(K23,Perfiles!$A$2:$A$5,0)),"") -> Cloud Computing | N23: Pendiente | O23: =IF(N23="Hecho","Sí","No") -> No
A24: P2-02 | B24: 2 | C24: 2 | D24: 07-nov-2026 | E24: Datos | F24: Cargar Bronze (GCS + BigQuery) | G24: CSV primero, imágenes después; tablas externas y nativa particionada | H24: retail_bronze.* | I24: python ops.py subir-datos; python ops.py bronze | J24: P2-01 | K24: Nicole Arenas | L24: =IFERROR(INDEX(Perfiles!$B$2:$B$5,MATCH(K24,Perfiles!$A$2:$A$5,0)),"") -> Datos + API + Modelado | M24: Winston Quispe | N24: Pendiente | O24: =IF(N24="Hecho","Sí","No") -> No | P24: SQL y script listos
A25: P2-03 | B25: 2 | C25: 3 | D25: 07-nov-2026 | E25: Datos | F25: Silver con Spark | G25: Tipado, nulos, cuarentena con motivo, Parquet particionado, reporte conciliado | H25: pipelines/batch/silver_hm.py | I25: python ops.py silver | J25: P2-02 | K25: Nicole Arenas | L25: =IFERROR(INDEX(Perfiles!$B$2:$B$5,MATCH(K25,Perfiles!$A$2:$A$5,0)),"") -> Datos + API + Modelado | M25: Winston Quispe | N25: Listo para desplegar | O25: =IF(N25="Hecho","Sí","No") -> No | P25: Local: 546,741 filas, 3 rechazos inyectados detectados, conciliado; corregido fn/active
A26: P2-04 | B26: 2 | C26: 4 | D26: 07-nov-2026 | E26: Datos | F26: Silver en BigQuery + vista de eventos | G26: LOAD DATA de Parquet; eventos deduplicados por event_id | H26: sql/silver/01_load_silver.sql | I26: python ops.py silver | J26: P2-03 | K26: Nicole Arenas | L26: =IFERROR(INDEX(Perfiles!$B$2:$B$5,MATCH(K26,Perfiles!$A$2:$A$5,0)),"") -> Datos + API + Modelado | N26: Listo para desplegar | O26: =IF(N26="Hecho","Sí","No") -> No
A27: P2-05 | B27: 2 | C27: 5 | D27: 07-nov-2026 | E27: Modelado | F27: Gold: modelo estrella | G27: fact_sales, fact_orders, dim_article/customer/date/channel | H27: sql/gold/01_gold_model.sql | I27: python ops.py gold | J27: P2-04 | K27: Nicole Arenas | L27: =IFERROR(INDEX(Perfiles!$B$2:$B$5,MATCH(K27,Perfiles!$A$2:$A$5,0)),"") -> Datos + API + Modelado | M27: Estuardo Oliver | N27: Listo para desplegar | O27: =IF(N27="Hecho","Sí","No") -> No
A28: P2-06 | B28: 2 | C28: 6 | D28: 07-nov-2026 | E28: Streaming | F28: Replay de eventos 2026 | G28: Transacciones reales re-emitidas con event_id idempotente | H28: ingestion/streaming/replay_publisher.py | I28: python ops.py replay | J28: P2-01 | K28: Winston Quispe | L28: =IFERROR(INDEX(Perfiles!$B$2:$B$5,MATCH(K28,Perfiles!$A$2:$A$5,0)),"") -> Cloud Computing | N28: Listo para desplegar | O28: =IF(N28="Hecho","Sí","No") -> No | P28: Dry-run sobre datos reales OK
A29: P2-07 | B29: 2 | C29: 7 | D29: 07-nov-2026 | E29: Streaming | F29: Ruta económica Pub/Sub -> BigQuery | G29: Suscripción BigQuery con DLQ | H29: infra/terraform/main.tf | J29: P2-01 | K29: Winston Quispe | L29: =IFERROR(INDEX(Perfiles!$B$2:$B$5,MATCH(K29,Perfiles!$A$2:$A$5,0)),"") -> Cloud Computing | N29: Listo para desplegar | O29: =IF(N29="Hecho","Sí","No") -> No
A30: P2-08 | B30: 2 | C30: 8 | D30: 07-nov-2026 | E30: Streaming | F30: Pipeline Dataflow | G30: Validación, dedup, ventanas 1 min, datos tardíos, DLQ, lag p50/p95 | H30: pipelines/streaming/dataflow_events.py | I30: python ops.py dataflow-iniciar / dataflow-detener | J30: P2-06 | K30: Winston Quispe | L30: =IFERROR(INDEX(Perfiles!$B$2:$B$5,MATCH(K30,Perfiles!$A$2:$A$5,0)),"") -> Cloud Computing | M30: Nicole Arenas | N30: Listo para desplegar | O30: =IF(N30="Hecho","Sí","No") -> No | P30: DirectRunner: 350 mensajes -> 300 únicos, 2 a DLQ
A31: P2-09 | B31: 2 | C31: 9 | D31: 07-nov-2026 | E31: ML | F31: Popularidad y catálogo de servicio | G31: reco_popular y v_catalog_serving en Gold | H31: sql/gold/01_gold_model.sql | I31: python ops.py gold | J31: P2-05 | K31: Estuardo Oliver | L31: =IFERROR(INDEX(Perfiles!$B$2:$B$5,MATCH(K31,Perfiles!$A$2:$A$5,0)),"") -> ML / Analytics | M31: Nicole Arenas | N31: Listo para desplegar | O31: =IF(N31="Hecho","Sí","No") -> No
A32: P2-10 | B32: 2 | C32: 10 | D32: 07-nov-2026 | E32: ML | F32: Recomendador baseline + evaluación | G32: Split temporal, MAP@12: popularidad vs recompra | H32: docs/evaluacion_recomendador.md | I32: python pipelines/reco/baseline_eval.py | K32: Estuardo Oliver | L32: =IFERROR(INDEX(Perfiles!$B$2:$B$5,MATCH(K32,Perfiles!$A$2:$A$5,0)),"") -> ML / Analytics | N32: Hecho | O32: =IF(N32="Hecho","Sí","No") -> Sí | P32: MAP@12 0.00875 vs 0.02622 (+200%)
A33: P2-11 | B33: 2 | C33: 11 | D33: 07-nov-2026 | E33: Datos | F33: Diccionario de datos | G33: Columnas, reglas y linaje Silver/Gold/ops/OLTP | H33: docs/diccionario_datos.md | K33: Nicole Arenas | L33: =IFERROR(INDEX(Perfiles!$B$2:$B$5,MATCH(K33,Perfiles!$A$2:$A$5,0)),"") -> Datos + API + Modelado | N33: Hecho | O33: =IF(N33="Hecho","Sí","No") -> Sí
A34: P2-12 | B34: 2 | C34: 12 | D34: 07-nov-2026 | E34: BI | F34: Vistas para tableros | G34: Ventas mensuales, top artículos, recurrencia, salud streaming | H34: sql/gold/02_kpi_views.sql | I34: python ops.py gold | J34: P2-05 | K34: Gianmarco Mejia | L34: =IFERROR(INDEX(Perfiles!$B$2:$B$5,MATCH(K34,Perfiles!$A$2:$A$5,0)),"") -> Dashboard / BI | M34: Nicole Arenas | N34: Listo para desplegar | O34: =IF(N34="Hecho","Sí","No") -> No
A35: P2-13 | B35: 2 | C35: 13 | D35: 07-nov-2026 | E35: BI | F35: Dashboard borrador | G35: Primer tablero Looker Studio sobre las vistas Gold | H35: Enlace Looker Studio | J35: P2-12 | K35: Gianmarco Mejia | L35: =IFERROR(INDEX(Perfiles!$B$2:$B$5,MATCH(K35,Perfiles!$A$2:$A$5,0)),"") -> Dashboard / BI | N35: Pendiente | O35: =IF(N35="Hecho","Sí","No") -> No
A36: P2-14 | B36: 2 | C36: 14 | D36: 07-nov-2026 | E36: Gestión | F36: Informe Entrega 2 | G36: Evidencias: conteos, reporte de calidad, capturas | H36: Word Entrega 2 | J36: P2-02..P2-13 | K36: Estuardo Oliver | L36: =IFERROR(INDEX(Perfiles!$B$2:$B$5,MATCH(K36,Perfiles!$A$2:$A$5,0)),"") -> ML / Analytics | M36: Todo el equipo | N36: Pendiente | O36: =IF(N36="Hecho","Sí","No") -> No
A37: P3-01 | B37: 3 | C37: 1 | D37: 20-nov-2026 | E37: API | F37: API FastAPI | G37: Catálogo, recomendaciones, asistente, carrito, checkout, wallet, pedidos, métricas, OpenAPI /docs | H37: api/main.py | I37: python ops.py local | K37: Nicole Arenas | L37: =IFERROR(INDEX(Perfiles!$B$2:$B$5,MATCH(K37,Perfiles!$A$2:$A$5,0)),"") -> Datos + API + Modelado | M37: Winston Quispe | N37: Listo para desplegar | O37: =IF(N37="Hecho","Sí","No") -> No | P37: Pruebas automáticas OK
A38: P3-02 | B38: 3 | C38: 2 | D38: 20-nov-2026 | E38: API | F38: Wallet transaccional | G38: Ledger append-only, ACID, idempotencia, sin sobregiro, confirmación explícita | H38: api/schema.sql | I38: python -m unittest discover -s tests | K38: Nicole Arenas | L38: =IFERROR(INDEX(Perfiles!$B$2:$B$5,MATCH(K38,Perfiles!$A$2:$A$5,0)),"") -> Datos + API + Modelado | N38: Listo para desplegar | O38: =IF(N38="Hecho","Sí","No") -> No | P38: Test: doble clic = 1 cobro; 409 sin saldo
A39: P3-03 | B39: 3 | C39: 3 | D39: 20-nov-2026 | E39: ML | F39: Asistente Vertex AI Gemini | G39: Gemini 3.1 Flash-Lite interpreta; backend busca en catálogo real; respaldo por reglas | H39: api/assistant.py | I39: config/control_plataforma.json: assistant_mode = gemini | J39: P2-01 | K39: Estuardo Oliver | L39: =IFERROR(INDEX(Perfiles!$B$2:$B$5,MATCH(K39,Perfiles!$A$2:$A$5,0)),"") -> ML / Analytics | M39: Nicole Arenas | N39: Listo para desplegar | O39: =IF(N39="Hecho","Sí","No") -> No | P39: Reglas probadas con catálogo real; Gemini requiere GCP
A40: P3-04 | B40: 3 | C40: 4 | D40: 20-nov-2026 | E40: ML | F40: Recomendaciones en API | G40: Perfil por grupo + popularidad; cold-start explícito | H40: api/main.py | K40: Estuardo Oliver | L40: =IFERROR(INDEX(Perfiles!$B$2:$B$5,MATCH(K40,Perfiles!$A$2:$A$5,0)),"") -> ML / Analytics | N40: Listo para desplegar | O40: =IF(N40="Hecho","Sí","No") -> No
...

Sheet Perfiles
A1: Integrante | B1: Perfil | C1: Responsabilidad | D1: Tareas | E1: Hechas | F1: Listas p/desplegar | G1: Pendientes | H1: % hecho
A2: Estuardo Oliver | B2: ML / Analytics | C2: Chatbot con Vertex AI Gemini, analítica, recomendaciones; integra documentos y demo. | D2: =COUNTIF(Matriz!$K$2:$K$52,A2) -> 11 | E2: =COUNTIFS(Matriz!$K$2:$K$52,$A2,Matriz!$N$2:$N$52,"Hecho") -> 5 | F2: =COUNTIFS(Matriz!$K$2:$K$52,$A2,Matriz!$N$2:$N$52,"Listo para desplegar") -> 3 | G2: =COUNTIFS(Matriz!$K$2:$K$52,$A2,Matriz!$N$2:$N$52,"Pendiente") -> 3 | H2: =IF(D2>0,E2/D2,0) -> 0.45454545
A3: Winston Quispe | B3: Cloud Computing | C3: Todo lo nube: Terraform, IAM, GCS, Pub/Sub, Dataflow (ingesta streaming), CI/CD, costos, DRP. | D3: =COUNTIF(Matriz!$K$2:$K$52,A3) -> 18 | E3: =COUNTIFS(Matriz!$K$2:$K$52,$A3,Matriz!$N$2:$N$52,"Hecho") -> 5 | F3: =COUNTIFS(Matriz!$K$2:$K$52,$A3,Matriz!$N$2:$N$52,"Listo para desplegar") -> 8 | G3: =COUNTIFS(Matriz!$K$2:$K$52,$A3,Matriz!$N$2:$N$52,"Pendiente") -> 5 | H3: =IF(D3>0,E3/D3,0) -> 0.27777778
A4: Nicole Arenas | B4: Datos + API + Modelado | C4: Bronze/Silver/Gold, calidad, modelo estrella, FastAPI y base transaccional. | D4: =COUNTIF(Matriz!$K$2:$K$52,A4) -> 13 | E4: =COUNTIFS(Matriz!$K$2:$K$52,$A4,Matriz!$N$2:$N$52,"Hecho") -> 5 | F4: =COUNTIFS(Matriz!$K$2:$K$52,$A4,Matriz!$N$2:$N$52,"Listo para desplegar") -> 6 | G4: =COUNTIFS(Matriz!$K$2:$K$52,$A4,Matriz!$N$2:$N$52,"Pendiente") -> 2 | H4: =IF(D4>0,E4/D4,0) -> 0.38461538
A5: Gianmarco Mejia | B5: Dashboard / BI | C5: KPIs, Looker Studio, calculadora y tablero de costos, diagramas y slides. | D5: =COUNTIF(Matriz!$K$2:$K$52,A5) -> 9 | E5: =COUNTIFS(Matriz!$K$2:$K$52,$A5,Matriz!$N$2:$N$52,"Hecho") -> 3 | F5: =COUNTIFS(Matriz!$K$2:$K$52,$A5,Matriz!$N$2:$N$52,"Listo para desplegar") -> 1 | G5: =COUNTIFS(Matriz!$K$2:$K$52,$A5,Matriz!$N$2:$N$52,"Pendiente") -> 5 | H5: =IF(D5>0,E5/D5,0) -> 0.33333333

Sheet Despliegue
A1: Paso | B1: # | C1: Acción | D1: Comando | E1: Responsable | F1: Insumo del JSON de control | G1: Verificación
A2: 1 | B2: D01 | C2: Instalar herramientas | D2: Google Cloud CLI, Terraform >= 1.6, Python 3.10-3.12, git (o usar Cloud Shell, que ya las trae) | E2: Winston Quispe | G2: gcloud --version; terraform -version
A3: 1 | B3: D02 | C3: Crear proyecto y vincular facturación | D3: gcloud projects create <project_id>; gcloud billing projects link <project_id> --billing-account=<cuenta> | E3: Winston Quispe | F3: Parametros: project_id, billing_account | G3: Proyecto con facturación en consola
A4: 1 | B4: D03 | C4: Completar el JSON de control | D4: Editar con `python ops.py panel` (o a mano) los campos marcados editables de config/control_plataforma.json: mínimo project_id y emails del equipo | E4: Todo el equipo | F4: Parametros, Usuarios | G4: python ops.py config sin errores
A5: 1 | B5: D04 | C5: Autenticarse | D5: gcloud auth login; gcloud auth application-default login (en Cloud Shell no hace falta) | E5: Todo el equipo | G5: gcloud config list
A6: 1 | B6: D05 | C6: Instalar dependencias | D6: pip install -r requirements.txt | E6: Todo el equipo | G6: python ops.py estado
A7: 1 | B7: D06 | C7: Publicar repo | D7: git remote add origin https://github.com/OWNER/REPO.git; git push -u origin main | E7: Estuardo Oliver | F7: Parametros: github_repo | G7: Workflow ci en verde
A8: 2 | B8: D07 | C8: Preparar proyecto | D8: python ops.py bootstrap | E8: Winston Quispe | F8: APIs, Parametros: region, dataproc_subnet, bucket_tfstate_suffix | G8: APIs activas, bucket de estado, terraform init
A9: 2 | B9: D08 | C9: Revisar plan | D9: python ops.py plan | E9: Winston Quispe | F9: Todas las hojas | G9: Plan sin errores; recursos esperados
A10: 2 | B10: D09 | C10: Crear infraestructura | D10: python ops.py apply | E10: Winston Quispe | F10: Todas las hojas | G10: Buckets, datasets, tablas, Pub/Sub, IAM, Cloud SQL, Cloud Run
A11: 2 | B11: D10 | C11: Subir datos H&M (desde la PC con data/raw) | D11: python ops.py subir-datos (imágenes: --con-imagenes) | E11: Nicole Arenas | F11: Parametros: local_raw_dir, bucket_raw_suffix | G11: gs://<bucket raw>/hm/*.csv
A12: 2 | B12: D11 | C12: Bronze | D12: python ops.py bronze | E12: Nicole Arenas | F12: Datasets, Tablas | G12: 31,788,324 filas en bronze.transactions
A13: 2 | B13: D12 | C13: Silver (Serverless Spark) | D13: python ops.py silver | E13: Nicole Arenas | F13: Parametros: dataproc_runtime | G13: _quality_report conciliado=true
A14: 2 | B14: D13 | C14: Gold y vistas BI | D14: python ops.py gold | E14: Nicole Arenas | F14: Parametros: price_demo_factor | G14: Tablas fact_/dim_ y vistas v_*
A15: 2 | B15: D14 | C15: Streaming de prueba | D15: python ops.py dataflow-iniciar; python ops.py replay; python ops.py dataflow-detener | E15: Winston Quispe | F15: Parametros: dataflow_*, replay_* | G15: Filas en ops.stream_metrics_1m y silver.v_events
A16: 3 | B16: D15 | C16: API, web y catálogo | D16: python ops.py api | E16: Nicole Arenas | F16: Parametros: cloudrun_*, assistant_mode, gemini_model; Usuarios (app) | G16: URL pública; /ready con 105,542 artículos
A17: 3 | B17: D16 | C17: Verificar contra el JSON de control | D17: python ops.py verificar | E17: Todo el equipo | F17: Tablas, Columnas | G17: Matriz tabla por tabla: OK / FALTA / DIFERENTE
A18: 3 | B18: D17 | C18: Despliegue desde GitHub | D18: python ops.py github -> crear variable GCP_WIF_PROVIDER -> Actions > deploy-api | E18: Winston Quispe | F18: Parametros: github_repo | G18: Workflow deploy-api en verde
... A21: 3 | B21: D20 | C21: Apagado | D21: python ops.py dataflow-detener; python ops.py destroy | E21: Winston Quispe | F21: Parametros: force_destroy_buckets | G21: Facturación diaria ~0
